Workbook

Sheet Dados
A1: Ano | B1: West Germany | C1: USA | D1: UK | E1: Austria | F1: Belgium | G1: Denmark | H1: France | I1: Italy | J1: Netherlands | K1: Norway | L1: Switzerland | M1: Japan | N1: Greece | O1: Portugal | P1: Spain | Q1: Australia | R1: New Zealand | S1: Alemanha Sintética | T1: Gap (Efeito) | U1: Gap²
A2: 1960 | B2: 2284 | C2: 2879 | D2: 2158 | E2: 1796 | F2: 1782 | G2: 2329 | H2: 1858 | I2: 1620 | J2: 2113 | K2: 1713 | L2: 3387 | M2: 1010 | N2: 707 | O2: 728 | P2: 1074 | Q2: 2373 | R2: 2545 | S2: {=MMULT(C2:R45,'Pesos Países (W)'!C4:C19)} -> 2117.0058 | T2: =B2-S2 -> 166.9942 | U2: =T2^2 -> 27887.064
A3: 1961 | B3: 2388 | C3: 2929 | D3: 2216 | E3: 1899 | F3: 1883 | G3: 2485 | H3: 1959 | I3: 1763 | J3: 2111 | K3: 1823 | L3: 3625 | M3: 1143 | N3: 1028 | O3: 783 | P3: 1201 | Q3: 2346 | R3: 2659 | S3: 2218.6532 | T3: =B3-S3 -> 169.34681 | U3: =T3^2 -> 28678.341
A4: 1962 | B4: 2527 | C4: 3103 | D4: 2276 | E4: 1977 | F4: 2018 | G4: 2665 | H4: 2099 | I4: 1900 | J4: 2275 | K4: 1905 | L4: 3788 | M4: 1262 | N4: 1049 | O4: 848 | P4: 1335 | Q4: 2539 | R4: 2713 | S4: 2341.5266 | T4: =B4-S4 -> 185.47335 | U4: =T4^2 -> 34400.365
A5: 1963 | B5: 2610 | C5: 3227 | D5: 2386 | E5: 2074 | F5: 2122 | G5: 2700 | H5: 2205 | I5: 2021 | J5: 2360 | K5: 1991 | L5: 3946 | M5: 1374 | N5: 1188 | O5: 905 | P5: 1467 | Q5: 2717 | R5: 2866 | S5: 2452.5164 | T5: =B5-S5 -> 157.48363 | U5: =T5^2 -> 24801.094
A6: 1964 | B6: 2806 | C6: 3420 | D6: 2534 | E6: 2224 | F6: 2288 | G6: 2980 | H6: 2367 | I6: 2093 | J6: 2566 | K6: 2112 | L6: 4158 | M6: 1546 | N6: 1316 | O6: 979 | P6: 1554 | Q6: 2873 | R6: 3001 | S6: 2627.3278 | T6: =B6-S6 -> 178.67221 | U6: =T6^2 -> 31923.758
A7: 1965 | B7: 3005 | C7: 3667 | D7: 2660 | E7: 2336 | F7: 2414 | G7: 3177 | H7: 2526 | I7: 2205 | J7: 2739 | K7: 2268 | L7: 4360 | M7: 1647 | N7: 1492 | O7: 1084 | P7: 1678 | Q7: 2973 | R7: 3224 | S7: 2782.9171 | T7: =B7-S7 -> 222.08289 | U7: =T7^2 -> 49320.81
A8: 1966 | B8: 3168 | C8: 3974 | D8: 2794 | E8: 2537 | F8: 2559 | G8: 3377 | H8: 2728 | I8: 2400 | J8: 2874 | K8: 2417 | L8: 4575 | M8: 1889 | N8: 1634 | O8: 1170 | P8: 1841 | Q8: 3230 | R8: 3481 | S8: 3008.8723 | T8: =B8-S8 -> 159.12771 | U8: =T8^2 -> 25321.627
A9: 1967 | B9: 3241 | C9: 4154 | D9: 2923 | E9: 2668 | F9: 2719 | G9: 3580 | H9: 2915 | I9: 2624 | J9: 3078 | K9: 2620 | L9: 4790 | M9: 2133 | N9: 1754 | O9: 1293 | P9: 1954 | Q9: 3404 | R9: 3360 | S9: 3184.185 | T9: =B9-S9 -> 56.815006 | U9: =T9^2 -> 3227.945
A10: 1968 | B10: 3571 | C10: 4494 | D10: 3173 | E10: 2908 | F10: 2958 | G10: 3892 | H10: 3163 | I10: 2910 | J10: 3399 | K10: 2784 | L10: 5138 | M10: 2496 | N10: 1967 | O10: 1475 | P10: 2160 | Q10: 3788 | R10: 3489 | S10: 3484.5123 | T10: =B10-S10 -> 86.487708 | U10: =T10^2 -> 7480.1237
A11: 1969 | B11: 3998 | C11: 4805 | D11: 3391 | E11: 3239 | F11: 3308 | G11: 4352 | H11: 3531 | I11: 3227 | J11: 3951 | K11: 3035 | L11: 5645 | M11: 2917 | N11: 2298 | O11: 1592 | P11: 2447 | Q11: 4162 | R11: 3969 | S11: 3864.6636 | T11: =B11-S11 -> 133.33642 | U11: =T11^2 -> 17778.601
A12: 1970 | B12: 4367 | C12: 4999 | D12: 3615 | E12: 3732 | F12: 3797 | G12: 4541 | H12: 3857 | I12: 3602 | J12: 4342 | K12: 3213 | L12: 6382 | M12: 3293 | N12: 2631 | O12: 1916 | P12: 2715 | Q12: 4490 | R12: 4136 | S12: 4290.6892 | T12: =B12-S12 -> 76.310812 | U12: =T12^2 -> 5823.3401
A13: 1971 | B13: 4686 | C13: 5362 | D13: 3854 | E13: 4100 | F13: 4129 | G13: 4858 | H13: 4203 | I13: 3834 | J13: 4705 | K13: 3523 | L13: 6938 | M13: 3575 | N13: 2988 | O13: 2153 | P13: 2951 | Q13: 4677 | R13: 4438 | S13: 4664.1628 | T13: =B13-S13 -> 21.837184 | U13: =T13^2 -> 476.8626
A14: 1972 | B14: 5055 | C14: 5838 | D14: 4149 | E14: 4513 | F14: 4512 | G14: 5262 | H14: 4535 | I14: 4101 | J14: 4984 | K14: 3814 | L14: 7406 | M14: 3988 | N14: 3383 | O14: 2420 | P14: 3293 | Q14: 5013 | R14: 4780 | S14: 5084.4453 | T14: =B14-S14 -> -29.445323 | U14: =T14^2 -> 867.02706
... A45: 2003 | B45: 28855 | C45: 37548 | D45: 29609 | E45: 30796 | F45: 30082 | G45: 30853 | H45: 29210 | I45: 27537 | J45: 31792 | K45: 37245 | L45: 33516 | M45: 28071 | N45: 20479 | O45: 17603 | P45: 24812 | Q45: 31273 | R45: 23728 | S45: 32227.807 | T45: =B45-S45 -> -3372.8071 | U45: =T45^2 -> 11375828
A47: MSPE | D47: =AVERAGE(U2:U31) -> 14313.624
A48: RMSPE Pré (1960-1989): | D48: =SQRT(AVERAGE(U2:U31)) -> 119.63956
A49: RMSPE Pós (1990-2003): | D49: =SQRT(AVERAGE(U32:U45)) -> 1945.8446
D50: =SQRT(AVERAGE(U2:U45)) -> 1102.0411

Sheet Pesos Países (W)
A1: PESOS ÓTIMOS DOS PAÍSES (W)
A3: Index | B3: País | C3: Peso (w)
A4: 1 | B4: USA | C4: 0.2186942
A5: 2 | B5: UK | C5: 0.0009650793
A6: 3 | B6: Austria | C6: 0.4175261
A7: 4 | B7: Belgium | C7: 0.0011693951
A8: 5 | B8: Denmark | C8: 0.0010507881
A9: 6 | B9: France | C9: 0.0008147026
A10: 8 | B10: Italy | C10: 0.0005029538
A11: 9 | B11: Netherlands | C11: 0.090285529
A12: 10 | B12: Norway | C12: 0.0005151888
A13: 12 | B13: Switzerland | C13: 0.1113089
A14: 14 | B14: Japan | C14: 0.15507989
A15: 16 | B15: Greece | C15: 0.0002918951
... A19: 21 | B19: New Zealand | C19: 0.0004332223
B21: SOMA: | C21: =SUM(C4:C19) -> 1

Sheet Pesos Preditores (V)
A1: PESOS ÓTIMOS DOS PREDITORES (V)
A3: # | B3: Preditor | C3: Peso V
A4: 1 | B4: GDP (média 1981-1990) | C4: 0.441
A5: 2 | B5: Trade (média 1981-1990) | C5: 0.134
A6: 3 | B6: Infrate (média 1981-1990) | C6: 0.072
A7: 4 | B7: Industry (média 1981-1990) | C7: 0.001
A8: 5 | B8: Schooling (média 1980,1985) | C8: 0.107
A9: 6 | B9: Invest80 (1980) | C9: 0.245
B11: SOMA: | C11: =SUM(C4:C9) -> 1

Sheet Dados-Industry
A1: DADOS: 4. DADOS-INDUSTRY
A3: Ano | B3: West Germany | C3: Australia | D3: Austria | E3: Belgium | F3: Denmark | G3: France | H3: Greece | I3: Italy | J3: Japan | K3: Netherlands | L3: New Zealand | M3: Norway | N3: Portugal | O3: Spain | P3: Switzerland | Q3: UK | R3: USA | S3: Alemanha Sintetica
A4: 1960 | B4: 44.987244
A5: 1961
A6: 1962
A7: 1963
A8: 1964
A9: 1965
A10: 1966
A11: 1967
A12: 1968
A13: 1969
A14: 1970 | B14: 38.217014 | P14: 36.266361
A15: 1971 | B15: 48.001259 | C15: 37.293591 | D15: 41.21851 | E15: 42.50227 | F15: 31.78034 | G15: 38.649269 | H15: 36.11808 | I15: 40.38538 | J15: 45.170719 | K15: 37.20113 | L15: 34.0294 | M15: 31.944679 | N15: 35.13776 | O15: 40.667221 | P15: 35.986961 | Q15: 43.07859 | R15: 34.508629
A16: 1972 | B16: 46.946892 | C16: 36.80088 | D16: 41.525631 | E16: 41.944149 | F16: 31.531469 | G16: 38.697899 | H16: 36.32357 | I16: 39.51487 | J16: 44.578239 | K16: 36.960201 | L16: 33.208939 | M16: 32.230431 | N16: 35.945591 | O16: 41.693291 | P16: 35.707561 | Q16: 42.560081 | R16: 34.44429
A17: 1973 | B17: 46.534359 | C17: 35.435848 | D17: 42.23682 | E17: 42.515091 | F17: 30.284731 | G17: 37.94067 | H17: 36.534939 | I17: 40.68504 | J17: 45.357731 | K17: 36.77002 | L17: 32.451801 | M17: 32.272209 | N17: 35.963459 | O17: 42.23267 | P17: 35.428162 | Q17: 42.135399 | R17: 34.37521
A18: 1974 | B18: 45.70887 | C18: 36.886761 | D18: 42.260269 | E18: 43.293011 | F18: 29.58704 | G18: 37.567768 | H18: 34.111149 | I18: 42.32259 | J18: 43.6329 | K18: 36.934269 | L18: 35.516602 | M18: 33.086529 | N18: 37.544479 | O18: 43.172298 | P18: 35.148766 | Q18: 41.623749 | R18: 34.03606
A19: 1975 | B19: 43.37009 | C19: 37.104549 | D19: 40.128139 | E19: 40.01701 | F19: 29.250561 | G19: 37.66209 | H19: 33.06773 | I19: 41.31369 | J19: 41.405479 | K19: 35.57053 | L19: 34.529041 | M19: 34.624119 | N19: 35.211498 | O19: 42.083221 | P19: 34.776234 | Q19: 40.488178 | R19: 33.22567
A20: 1976 | B20: 43.613609 | C20: 36.665291 | D20: 39.3979 | E20: 40.133949 | F20: 28.24987 | G20: 37.490768 | H20: 33.04417 | I20: 42.21162 | J20: 41.4841 | K20: 35.763512 | L20: 34.712021 | M20: 34.209702 | N20: 34.72538 | O20: 41.384251 | P20: 34.496834 | Q20: 41.08992 | R20: 33.760849
A21: 1977 | B21: 43.166019 | C21: 35.999359 | D21: 39.05883 | E21: 39.495281 | F21: 28.02203 | G21: 36.88102 | H21: 33.730728 | I21: 41.67762 | J21: 40.436939 | K21: 35.207821 | L21: 32.954659 | M21: 34.076401 | N21: 34.724171 | O21: 40.521809 | P21: 34.217438 | Q21: 41.33041 | R21: 34.264641
A22: 1978 | B22: 42.96508 | C22: 35.652821 | D22: 39.235649 | E22: 38.45702 | F22: 27.56307 | G22: 36.230061 | H22: 32.863369 | I22: 41.045071 | J22: 40.692162 | K22: 34.131889 | L22: 32.50108 | M22: 35.433521 | N22: 33.15321 | O22: 39.432571 | P22: 33.938038 | Q22: 41.465809 | R22: 34.037231
A23: 1979 | B23: 43.08099 | C23: 35.81057 | D23: 38.1772 | E23: 38.20924 | F23: 26.88064 | G23: 35.840729 | H23: 34.108978 | I23: 40.675709 | J23: 40.600471 | K23: 34.084469 | L23: 32.65749 | M23: 38.279739 | N23: 31.947809 | O23: 38.965611 | P23: 33.658638 | Q23: 41.823872 | R23: 33.62648
A24: 1980 | B24: 36.04203 | C24: 37.026699 | D24: 38.09647 | E24: 36.84375 | F24: 28.233141 | G24: 36.0303 | H24: 32.9426 | I24: 40.379559 | J24: 41.000149 | K24: 34.517979 | L24: 32.18576 | M24: 40.388729 | N24: 32.877769 | O24: 38.567551 | P24: 32.869999 | Q24: 42.346298 | R24: 33.514389
A25: 1981 | B25: 35.423489 | C25: 35.924339 | D25: 37.830849 | E25: 34.465172 | F25: 26.577101 | G25: 35.172989 | H25: 32.571678 | I25: 39.038651 | J25: 40.91642 | K25: 34.746471 | L25: 34.01445 | M25: 40.68092 | N25: 33.93985 | O25: 37.673019 | P25: 32.689999 | Q25: 41.894661 | R25: 34.08828
A26: 1982 | B26: 34.778473 | C26: 34.743671 | D26: 36.904591 | E26: 34.4062 | F26: 26.75725 | G26: 34.09864 | H26: 30.660641 | I26: 38.13298 | J26: 40.320621 | K26: 34.068932 | L26: 34.555931 | M26: 40.848209 | N26: 33.645222 | O26: 37.06181 | P26: 32.200001 | Q26: 41.491692 | R26: 32.909691
... A33: 1989 | B33: 33.96273 | C33: 29.960911 | D33: 34.11145 | E33: 33.229431 | F33: 27.020679 | G33: 30.22196 | H33: 28.5359 | I33: 34.55434 | J33: 39.04401 | K33: 30.665979 | L33: 29.19099 | M33: 35.525398 | N33: 32.344391 | O33: 36.218159 | P33: 31.690001 | Q33: 36.629669 | R33: 28.61904
A34: 1990 | C34: 28.966801 | D34: 34.110531 | E34: 32.664299 | F34: 26.544291 | G34: 29.69998 | H34: 28.196739 | I34: 33.897999 | J34: 39.36253 | K34: 30.71949 | L34: 27.921921 | M34: 35.660439 | N34: 31.71348 | O34: 35.47665 | P34: 31.34 | Q34: 35.17424 | R34: 27.850321
A35: 1991 | C35: 28.167999 | D35: 33.98061 | E35: 30.661619 | F35: 26.169559 | G35: 29.520161 | H35: 26.528021 | I35: 32.910801 | J35: 39.023548 | K35: 30.41988 | L35: 27.339199 | M35: 34.552021 | N35: 30.284439 | O35: 34.688511 | P35: 30.790001 | Q35: 33.12701 | R35: 26.62006
A36: 1992 | C36: 27.971661 | D36: 33.033249 | E36: 30.110929 | F36: 26.345341 | G36: 29.157129 | H36: 25.66123 | I36: 32.388691 | J36: 37.858841 | K36: 29.345671 | L36: 27.11838 | M36: 34.170551 | N36: 30.2792 | O36: 32.8619 | P36: 29.99 | Q36: 31.889669 | R36: 25.72843
A37: 1993 | C37: 28.00918 | D37: 32.18623 | E37: 28.998671 | F37: 25.190121 | G37: 27.45125 | H37: 25.50778 | I37: 31.35425 | J37: 36.380058 | K37: 28.654131 | L37: 27.06921 | M37: 33.764042 | N37: 29.60257 | O37: 31.168209 | P37: 29.58 | Q37: 31.270929 | R37: 25.61001
A38: 1994 | C38: 28.139919 | D38: 32.138279 | E38: 28.923639 | F38: 25.311541 | G38: 27.18095 | H38: 24.36351 | I38: 31.301359 | J38: 34.927731 | K38: 28.54458 | L38: 27.76848 | M38: 34.258579 | N38: 30.643669 | O38: 30.55055 | P38: 30.41 | Q38: 31.693331 | R38: 26.082951
A39: 1995 | C39: 27.82765 | D39: 32.44965 | E39: 29.53443 | F39: 25.757509 | G39: 27.2759 | H39: 23.086691 | I39: 31.501289 | J39: 34.21719 | K39: 28.746229 | L39: 26.99032 | M39: 35.352779 | N39: 31.498079 | O39: 30.98291 | P39: 29.83 | Q39: 31.996481 | R39: 26.29285
A40: 1996 | C40: 27.10232 | D40: 32.29562 | E40: 29.14131 | F40: 25.95113 | G40: 26.606609 | H40: 23.02569 | I40: 30.502131 | J40: 33.91785 | K40: 28.43318 | L40: 26.742161 | M40: 37.7201 | N40: 31.741541 | O40: 30.45867 | P40: 28.809999 | Q40: 31.86726 | R40: 25.7854
A41: 1997 | C41: 27.076691 | D41: 32.726978 | E41: 29.257811 | F41: 26.045151 | G41: 26.041229 | H41: 21.59255 | I41: 30.06423 | J41: 33.713951 | K41: 27.830151 | L41: 26.50679 | M41: 38.262901 | N41: 31.63949 | O41: 30.441401 | P41: 28.190001 | Q41: 31.074129 | R41: 25.384291
A42: 1998 | C42: 26.283131 | D42: 32.84259 | E42: 28.63953 | F42: 26.000641 | G42: 25.945641 | H42: 22.343321 | I42: 29.91003 | J42: 32.704552 | K42: 27.106001 | L42: 25.276569 | M42: 33.82029 | N42: 31.13629 | O42: 30.196671 | P42: 27.43 | Q42: 29.46092 | R42: 25.018841
A43: 1999 | C43: 26.190729 | D43: 32.900028 | E43: 27.95392 | F43: 26.2223 | G43: 25.49264 | H43: 22.295839 | I43: 29.311411 | J43: 32.42955 | K43: 26.31304 | L43: 25.51298 | M43: 35.71146 | N43: 30.41585 | O43: 29.989201 | P43: 27.43 | Q43: 28.59877 | R43: 24.72505
A44: 2000 | C44: 25.566681 | D44: 32.774849 | E44: 28.08952 | F44: 27.18491 | G44: 25.48119 | H44: 22.828011 | I44: 29.04274 | J44: 32.231159 | K44: 26.798981 | L44: 25.291679 | M44: 42.95295 | N44: 29.99342 | O44: 30.193701 | P44: 26.76 | Q44: 28.47661 | R44: 24.443489
A45: 2001 | C45: 25.4391 | D45: 32.168598 | E45: 27.25738 | F45: 26.28203 | G45: 25.501699 | H45: 23.48645 | I45: 28.742929 | J45: 30.96192 | K45: 26.62816 | M45: 40.874199 | N45: 29.39245 | O45: 29.928841 | P45: 27.35 | Q45: 27.475519 | R45: 23.04858
A46: 2002 | C46: 25.94952 | D46: 31.984779 | E46: 27.01092 | F46: 26.400669 | G46: 25.308121 | H46: 23.21043 | I46: 28.28014 | J46: 30.39852 | K46: 25.827681 | M46: 37.908371 | N46: 28.688181 | O46: 29.684759 | P46: 26.780001 | Q46: 26.990379
A47: 2003 | D47: 31.737129 | E47: 26.484779 | F47: 26.40539 | G47: 24.47357 | H47: 23.830009 | I47: 27.804819 | M47: 37.516239 | O47: 29.586519 | P47: 26.450001 | Q47: 26.59016

Sheet Dados-Trade
A1: DADOS: 2. DADOS-TRADE
A3: Ano | B3: West Germany | C3: Australia | D3: Austria | E3: Belgium | F3: Denmark | G3: France | H3: Greece | I3: Italy | J3: Japan | K3: Netherlands | L3: New Zealand | M3: Norway | N3: Portugal | O3: Spain | P3: Switzerland | Q3: UK | R3: USA
A4: 1960 | B4: 35.459682 | C4: 31.266439 | D4: 48.126095 | E4: 77.341782 | F4: 65.782196 | G4: 26.919622 | H4: 21.312531 | I4: 26.573429 | J4: 20.954344 | K4: 90.887093 | L4: 52.548824 | M4: 73.680962 | N4: 37.353939 | O4: 16.249819 | P4: 53.253502 | Q4: 43.25547 | R4: 9.693181
A5: 1961 | B5: 33.836784 | C5: 29.821074 | D5: 46.525959 | E5: 80.016273 | F5: 61.540672 | G5: 26.21155 | H5: 21.172319 | I5: 26.883282 | J5: 20.123087 | K5: 88.212914 | L5: 52.944569 | M5: 72.139977 | N5: 39.982895 | O5: 17.638802 | P5: 54.593182 | Q5: 41.533241 | R5: 9.4446545
A6: 1962 | B6: 33.466377 | C6: 30.158545 | D6: 47.171013 | E6: 82.437759 | F6: 60.337379 | G6: 24.89856 | H6: 21.926023 | I6: 27.117237 | J6: 18.671103 | K6: 86.703773 | L6: 48.803684 | M6: 69.344788 | N6: 38.321789 | O6: 19.606129 | P6: 54.494743 | Q6: 40.404633 | R6: 9.4293242
A7: 1963 | B7: 34.160629 | C7: 32.055397 | D7: 47.977253 | E7: 85.66539 | F7: 60.416042 | G7: 25.005909 | H7: 23.088087 | I7: 27.785471 | J7: 18.86199 | K7: 87.91217 | L7: 53.844959 | M7: 70.439796 | N7: 39.377365 | O7: 19.67972 | P7: 53.69223 | Q7: 40.406586 | R7: 9.470706
A8: 1964 | B8: 34.566139 | C8: 31.527285 | D8: 48.415096 | E8: 86.620453 | F8: 61.678101 | G8: 25.622961 | H8: 23.294668 | I8: 26.755199 | J8: 19.13273 | K8: 86.539818 | L8: 50.796028 | M8: 71.781082 | N8: 50.419785 | O8: 21.492392 | P8: 53.660713 | Q8: 40.518764 | R8: 9.7258787
A9: 1965 | B9: 35.816799 | C9: 31.035599 | D9: 49.6133 | E9: 85.261909 | F9: 61.388741 | G9: 25.749504 | H9: 24.24564 | I9: 27.677755 | J9: 19.600803 | K9: 83.929771 | L9: 44.781643 | M9: 71.817253 | N9: 52.902737 | O9: 22.708794 | P9: 55.158588 | Q9: 39.225338 | R9: 9.7303467
A10: 1966 | B10: 36.628227 | C10: 29.973152 | D10: 50.31641 | E10: 89.370125 | F10: 59.872742 | G10: 26.475941 | H10: 24.71656 | I10: 29.030056 | J10: 19.557243 | K10: 82.381424 | L10: 45.967167 | M10: 72.533798 | N10: 52.805916 | O10: 23.890324 | P10: 55.518734 | Q10: 38.964634 | R10: 10.097592
A11: 1967 | B11: 37.226662 | C11: 30.114193 | D11: 49.683853 | E11: 86.239647 | F11: 57.854729 | G11: 26.188457 | H11: 23.642069 | I11: 29.300257 | J11: 19.05209 | K11: 79.591179 | L11: 39.779766 | M11: 74.773056 | N11: 51.549599 | O11: 21.74692 | P11: 54.613895 | Q11: 39.313187 | R11: 10.208102
A12: 1968 | B12: 39.09016 | C12: 28.348595 | D12: 50.410915 | E12: 90.623016 | F12: 57.879894 | G12: 26.57132 | H12: 23.103203 | I12: 29.876673 | J12: 19.074675 | K12: 79.654465 | L12: 44.663773 | M12: 73.59362 | N12: 49.794838 | O12: 24.657402 | P12: 56.837097 | Q12: 43.665131 | R12: 10.593937
A13: 1969 | B13: 40.571236 | C13: 29.821142 | D13: 54.232513 | E13: 97.949638 | F13: 58.468327 | G13: 28.73958 | H13: 23.465282 | I13: 31.844769 | J13: 19.484798 | K13: 82.784653 | L13: 46.908524 | M13: 72.030357 | N13: 48.176414 | O13: 26.033092 | P13: 60.69416 | Q13: 44.038982 | R13: 10.635633
A14: 1970 | B14: 40.318378 | C14: 28.962433 | D14: 59.711964 | E14: 100.42813 | F14: 60.321808 | G14: 31.085831 | H14: 23.462626 | I14: 32.854187 | J14: 20.330492 | K14: 88.73793 | L14: 48.324024 | M14: 74.139931 | N14: 50.211582 | O14: 27.450756 | P14: 63.589043 | Q14: 45.247738 | R14: 11.388641
A15: 1971 | B15: 39.739914 | C15: 27.807472 | D15: 59.185368 | E15: 97.975098 | F15: 58.494747 | G15: 31.760962 | H15: 23.728756 | I15: 33.224659 | J15: 20.702047 | K15: 88.536026 | L15: 45.481525 | M15: 73.002907 | N15: 51.907047 | O15: 27.574125 | P15: 60.333889 | Q15: 44.933399 | R15: 11.367576
... A34: 1990 | B34: 58.3615 | C34: 34.461769 | D34: 79.029663 | E34: 134.00658 | F34: 66.584679 | G34: 45.130569 | H34: 44.881191 | I34: 40.0452 | J34: 20.64731 | K34: 103.68212 | L34: 54.535011 | M34: 74.734642 | N34: 75.17775 | O34: 37.502689 | P34: 72.00161 | Q34: 51.467461 | R34: 21.18795
A35: 1991 | C35: 35.23764 | D35: 78.769096 | E35: 130.8264 | F35: 68.532112 | G35: 45.04747 | H35: 43.14999 | I35: 37.988586 | J35: 18.730829 | K35: 103.30096 | L35: 56.428131 | M35: 72.622849 | N35: 69.90818 | O35: 37.407082 | P35: 68.58638 | Q35: 48.209381 | R35: 21.26635
A36: 1992 | C36: 37.69257 | D36: 76.002907 | E36: 126.43597 | F36: 66.430893 | G36: 44.026119 | H36: 43.44936 | I36: 39.345406 | J36: 17.882681 | K36: 99.637871 | L36: 61.140541 | M36: 69.547249 | N36: 65.14225 | O36: 38.03965 | P36: 67.868607 | Q36: 49.349758 | R36: 21.54221
A37: 1993 | C37: 38.351791 | D37: 73.35833 | E37: 120.23799 | F37: 63.976089 | G37: 41.841209 | H37: 41.309959 | I37: 42.431316 | J37: 16.311211 | K37: 94.706429 | L37: 59.26334 | M37: 70.125801 | N37: 62.448689 | O37: 39.409481 | P37: 66.710213 | Q37: 52.593632 | R37: 21.55765
A38: 1994 | C38: 39.71843 | D38: 75.149643 | E38: 125.53788 | F38: 65.612671 | G38: 43.401379 | H38: 40.28257 | I38: 45.074287 | J38: 16.44124 | K38: 95.985481 | L38: 60.43647 | M38: 70.586227 | N38: 65.605721 | O38: 44.396439 | P38: 66.585632 | Q38: 54.257759 | R38: 22.618219
A39: 1995 | C39: 40.153259 | D39: 77.784943 | E39: 129.36067 | F39: 66.717857 | G39: 44.69141 | H39: 40.818081 | I39: 51.247398 | J39: 17.31402 | K39: 99.495033 | L39: 58.596111 | M39: 70.103203 | N39: 68.574448 | O39: 47.852901 | P39: 66.157257 | Q39: 57.896839 | R39: 24.273979
A40: 1996 | C40: 39.977379 | D40: 80.743919 | E40: 131.87495 | F40: 66.073807 | G40: 45.604462 | H40: 40.40134 | I40: 48.172119 | J40: 19.33235 | K40: 101.01143 | L40: 57.031071 | M40: 72.619583 | N40: 69.221817 | O40: 50.073299 | P40: 67.940277 | Q40: 59.849579 | R40: 24.58247
A41: 1997 | C41: 42.1768 | D41: 85.257927 | E41: 141.31438 | F41: 68.587067 | G41: 49.360401 | H41: 39.684841 | I41: 50.315632 | J41: 20.999901 | K41: 104.89993 | L41: 57.132099 | M41: 75.462173 | N41: 71.549889 | O41: 55.558651 | P41: 75.340652 | Q41: 57.84053 | R41: 25.591539
A42: 1998 | C42: 41.36496 | E42: 149.6824 | J42: 21.144987 | M42: 74.282089 | O42: 57.125301 | Q42: 55.989063 | R42: 24.690569
A43: 1999
A44: 2000
A45: 2001
A46: 2002
A47: 2003

Sheet Dados-Infrate
A1: DADOS: 3. DADOS-INFRATE
A3: Ano | B3: West Germany | C3: Australia | D3: Austria | E3: Belgium | F3: Denmark | G3: France | H3: Greece | I3: Italy | J3: Japan | K3: Netherlands | L3: New Zealand | M3: Norway | N3: Portugal | O3: Spain | P3: Switzerland | Q3: UK | R3: USA
A4: 1960
A5: 1961 | B5: 2.5157232 | C5: 2.5121319 | D5: 3.5422561 | E5: 0.98314607 | F5: 3.4516289 | G5: 2.414562 | H5: 1.934236 | I5: 2.702703 | J5: 5.404726 | K5: 1.732093 | L5: 1.830283 | M5: 2.451108 | N5: 1.5490021 | O5: 2.005919 | P5: 1.845371 | Q5: 3.5794179 | R5: 1.075182
A6: 1962 | B6: 2.7607362 | C6: -0.278474 | D6: 4.3817849 | E6: 1.404729 | F6: 7.37782 | G6: 5.2472501 | H6: -0.37950659 | I6: 3.9473679 | J6: 6.7731929 | K6: 2.2860379 | L6: 2.696079 | M6: 5.2685161 | N6: 2.662071 | O6: 5.6347589 | P6: 4.3156161 | Q6: 4.103672 | R6: 1.116071
A7: 1963 | B7: 2.9850745 | C7: 0.53057808 | D7: 2.70877 | E7: 2.1533401 | F7: 6.1050329 | G7: 4.9396901 | H7: 2.8571429 | I7: 7.5949368 | J7: 7.6613798 | K7: 3.343184 | L7: 1.909308 | M7: 2.5870409 | N7: 2.0215731 | O7: 8.8046274 | P7: 3.439719 | Q7: 2.0746889 | R7: 1.214128
A8: 1964 | B8: 2.3188405 | C8: 2.3611109 | D8: 3.868571 | E8: 4.1756182 | F8: 3.092783 | G8: 3.2293379 | H8: 0.92592591 | I8: 5.8823528 | J8: 3.8381741 | K8: 5.790884 | L8: 3.4348171 | M8: 5.679944 | N8: 3.4000001 | O8: 6.9501872 | P8: 3.0813141 | Q8: 3.2113819 | R8: 1.308615
A9: 1965 | B9: 3.3994334 | C9: 3.962008 | D9: 4.9309111 | E9: 4.0598021 | F9: 5.4499998 | G9: 2.71474 | H9: 3.119266 | I9: 4.4444451 | J9: 6.5934072 | K9: 5.794898 | L9: 3.3962259 | M9: 4.2595901 | N9: 3.4816251 | O9: 13.23638 | P9: 3.4145169 | Q9: 4.8050408 | R9: 1.668461
A10: 1966 | B10: 3.5616438 | C10: 2.975724 | D10: 2.2058821 | E10: 4.173892 | F10: 7.06496 | G10: 2.5707209 | H10: 4.9822059 | I10: 3.191489 | J10: 5.0796628 | K10: 5.7968702 | L10: 2.7737229 | M10: 3.2513371 | N10: 5.0467291 | O10: 6.1941152 | P10: 4.7761312 | Q10: 3.9083049 | R10: 2.9909999
A11: 1967 | B11: 1.5873016 | C11: 3.1939161 | D11: 3.9749999 | E11: 2.912852 | F11: 8.2078533 | G11: 2.8183191 | H11: 1.6949151 | I11: 3.092783 | J11: 3.977881 | K11: 3.486793 | L11: 6.107955 | M11: 4.4333949 | N11: 5.5160141 | O11: 6.4145751 | P11: 4.0214782 | Q11: 2.423146 | R11: 2.775636
A12: 1968 | B12: 1.0416666 | C12: 2.6529109 | D12: 2.773103 | E12: 2.7033269 | F12: 7.9536152 | G12: 4.5521288 | H12: 0.33333331 | I12: 2 | J12: 5.3697028 | K12: 3.6756129 | L12: 4.283802 | M12: 3.471534 | N12: 6.070827 | O12: 4.963315 | P12: 2.4123509 | Q12: 4.731638 | R12: 4.217721
A13: 1969 | B13: 2.0618556 | C13: 2.919359 | D13: 3.0804019 | E13: 3.7457819 | F13: 3.487931 | G13: 6.0393262 | H13: 2.491694 | I13: 1.960784 | J13: 5.2425919 | K13: 7.4282498 | L13: 4.8780489 | M13: 3.0674851 | N13: 7.4025121 | O13: 2.1244521 | P13: 2.489007 | Q13: 5.4619021 | R13: 5.414701
A14: 1970 | B14: 3.2828283 | C14: 3.9060681 | D14: 4.3728251 | E14: 3.9141281 | F14: 6.5148368 | G14: 5.8454752 | H14: 2.9173419 | I14: 4.807693 | J14: 7.6732669 | K14: 3.6799369 | L14: 6.548347 | M14: 10.56548 | N14: 4.5333328 | O14: 5.757617 | P14: 3.6160271 | Q14: 6.3618932 | R14: 5.8952961
A15: 1971 | B15: 5.1344743 | C15: 6.0639958 | D15: 4.7042618 | E15: 4.3405681 | F15: 5.8698769 | G15: 5.3975139 | H15: 2.992126 | I15: 5.5045872 | J15: 6.4169722 | K15: 7.4775801 | L15: 10.30303 | M15: 6.2584119 | N15: 7.4960752 | O15: 8.2360411 | P15: 6.5730128 | Q15: 9.4078751 | R15: 4.255929
A16: 1972 | B16: 5.3488374 | C16: 5.8649788 | D16: 6.3620629 | E16: 5.4475002 | F16: 6.5623479 | G16: 6.063004 | H16: 4.2813449 | I16: 5.217391 | J16: 4.8240218 | K16: 7.79175 | L16: 6.776557 | M16: 7.219759 | N16: 8.94487 | O16: 8.2893658 | P16: 6.660192 | Q16: 7.0879121 | R16: 3.3056149
... A43: 1999 | B43: 0.67307693 | C43: 1.465428 | D43: 0.56239301 | E43: 1.119242 | F43: 2.4786849 | G43: 0.5 | H43: 2.6367829 | I43: 1.655629 | J43: -0.33825591 | K43: 2.211071 | L43: -0.1245951 | M43: 2.3331389 | N43: 2.3038859 | O43: 2.310672 | P43: 0.82482988 | Q43: 1.555385 | R43: 2.1880269
A44: 2000 | C44: 4.475183 | D44: 2.350462 | E44: 2.5462461 | F44: 2.9247789 | G44: 1.691542 | H44: 3.150125 | I44: 2.5376871 | J44: -0.67052978 | K44: 2.5237801 | L44: 2.619761 | M44: 3.0860679 | N44: 2.8467209 | O44: 3.4326141 | P44: 1.5433919 | Q44: 2.9270999 | R44: 3.376857
A45: 2001 | C45: 4.3808408 | D45: 2.6599619 | E45: 2.4712729 | F45: 2.3499999 | G45: 1.6634049 | H45: 3.3749959 | I45: 2.785166 | J45: -0.73339438 | K45: 4.5342312 | L45: 2.6258211 | M45: 3.0173781 | N45: 4.3947568 | O45: 3.5911009 | P45: 0.98837209 | Q45: 1.820852 | R45: 2.8261709
A46: 2002 | C46: 3.003171 | D46: 1.810212 | E46: 1.643454 | F46: 2.4263151 | G46: 1.9249279 | H46: 3.6292281 | I46: 2.4653201 | J46: -0.91512048 | K46: 3.467068 | L46: 2.6770909 | M46: 1.288146 | N46: 3.5450521 | O46: 3.066777 | P46: 0.64150012 | Q46: 1.6344579 | R46: 1.586032
A47: 2003 | C47: 2.770735 | D47: 1.3634191 | E47: 1.5913121 | F47: 2.09062 | G47: 2.1010389 | H47: 3.5305569 | I47: 2.672559 | J47: -0.2541942 | K47: 2.11464 | L47: 1.753576 | M47: 2.4753971 | N47: 3.2833331 | O47: 3.033474 | P47: 0.6292392 | Q47: 2.9136319 | R47: 2.2700951

Sheet Dados-Schooling
A1: DADOS: 5. DADOS-SCHOOLING
A3: Ano | B3: West Germany | C3: Australia | D3: Austria | E3: Belgium | F3: Denmark | G3: France | H3: Greece | I3: Italy | J3: Japan | K3: Netherlands | L3: New Zealand | M3: Norway | N3: Portugal | O3: Spain | P3: Switzerland | Q3: UK | R3: USA
A4: 1960 | B4: 61 | C4: 50.400002 | D4: 48.700001 | E4: 27.1 | F4: 46.099998 | G4: 25.700001 | H4: 7.9000001 | I4: 13.9 | J4: 30.9 | K4: 11.1 | L4: 58 | M4: 21.299999 | N4: 3.5 | O4: 3.9000001 | P4: 21.799999 | Q4: 24.5 | R4: 43.799999
A5: 1961
A6: 1962
A7: 1963
A8: 1964
A9: 1965 | B9: 58.900002 | C9: 48.900002 | D9: 47.599998 | E9: 28.5 | F9: 45.5 | G9: 25.799999 | H9: 9.8000002 | I9: 14.1 | J9: 36.700001 | K9: 13.6 | L9: 54.299999 | M9: 22.4 | N9: 3.9000001 | O9: 4.5999999 | P9: 22.299999 | Q9: 26.5 | R9: 43.799999
A10: 1966
A11: 1967
A12: 1968
A13: 1969
A14: 1970 | B14: 57 | C14: 48.299999 | D14: 46.5 | E14: 28.700001 | F14: 44.5 | G14: 26 | H14: 10.6 | I14: 17.5 | J14: 33 | K14: 45.799999 | L14: 54.5 | M14: 31.1 | N14: 6.8000002 | O14: 5.8000002 | P14: 38 | Q14: 28.9 | R14: 44.400002
A15: 1971
A16: 1972
A17: 1973
A18: 1974
A19: 1975 | B19: 46.799999 | C19: 47 | D19: 45.599998 | E19: 30.299999 | F19: 44.900002 | G19: 26.799999 | H19: 12.9 | I19: 18.6 | J19: 38.099998 | K19: 44.299999 | L19: 57.099998 | M19: 34.799999 | N19: 9.6000004 | O19: 8.1999998 | P19: 36.400002 | Q19: 31 | R19: 42.599998
A20: 1976
A21: 1977
A22: 1978
A23: 1979
A24: 1980 | B24: 52.5 | C24: 47.5 | D24: 61.799999 | E24: 31.6 | F24: 43.400002 | G24: 34.5 | H24: 19.700001 | I24: 29.200001 | J24: 39.900002 | K24: 44.099998 | L24: 46.099998 | M24: 39.299999 | N24: 10.6 | O24: 13.3 | P24: 54.299999 | Q24: 32.900002 | R24: 62.900002
A25: 1981
A26: 1982
A27: 1983
A28: 1984
A29: 1985 | B29: 58.5 | C29: 48.400002 | D29: 60 | E29: 32.599998 | F29: 42.5 | G29: 36.299999 | H29: 23.700001 | I29: 30.299999 | J29: 41.900002 | K29: 44.700001 | L29: 46.599998 | M29: 41 | N29: 13.7 | O29: 17.6 | P29: 53.599998 | Q29: 35.700001 | R29: 57.400002
A30: 1986
A31: 1987
A32: 1988
A33: 1989
A34: 1990 | B34: 56.200001 | C34: 48.400002 | D34: 57.900002 | E34: 32.599998 | F34: 49.900002 | G34: 36.900002 | H34: 28.700001 | I34: 31.5 | J34: 44.5 | K34: 45.400002 | L34: 24.1 | M34: 69.599998 | N34: 14.8 | O34: 25.5 | P34: 53.799999 | Q34: 38.5 | R34: 44.400002
A35: 1991
A36: 1992
A37: 1993
A38: 1994
A39: 1995 | C39: 48.599998 | D39: 55.700001 | E39: 30.5 | F39: 47 | G39: 37.299999 | H39: 31.799999 | I39: 32.400002 | J39: 46.799999 | K39: 46.299999 | L39: 26.6 | M39: 66.699997 | N39: 14.7 | O39: 28.6 | P39: 54.799999 | Q39: 39.900002 | R39: 44.599998
A40: 1996
A41: 1997
...

Sheet Dados-Invest80
A1: DADOS: 6B. DADOS-INVEST80
A3: Ano | B3: West Germany | C3: Australia | D3: Austria | E3: Belgium | F3: Denmark | G3: France | H3: Greece | I3: Italy | J3: Japan | K3: Netherlands | L3: New Zealand | M3: Norway | N3: Portugal | O3: Spain | P3: Switzerland | Q3: UK | R3: USA
A4: 1960
A5: 1961
A6: 1962
A7: 1963
A8: 1964
A9: 1965
A10: 1966
A11: 1967
A12: 1968
A13: 1969
A14: 1970
A15: 1971
... A23: 1979
A24: 1980 | B24: 27.017998 | C24: 29.695999 | D24: 26.642 | E24: 21.875999 | F24: 22.217999 | G24: 27.236 | H24: 24.002001 | I24: 26.728001 | J24: 34.986 | K24: 21.84 | L24: 25.521999 | M24: 31.594 | N24: 26.488001 | O24: 24.568001 | P24: 30.963999 | Q24: 17.587999 | R24: 22.375999
A25: 1981
A26: 1982
A27: 1983
A28: 1984
A29: 1985
A30: 1986
A31: 1987
A32: 1988
A33: 1989
A34: 1990
A35: 1991
A36: 1992
... A47: 2003

Sheet Match Preditores
A1: CÁLCULO DO SCORE DE MINIMIZAÇÃO (SSR) - PONDERADO POR V
A3: Preditor | B3: Alemanha Real | C3: Alemanha Sintética | D3: Diferença | E3: Diferença² | F3: Peso V | G3: Diferença² × V
A4: GDP (média 1981-1990) | B4: =AVERAGE(Dados!B23:B32) -> 15808.9 | C4: =AVERAGE(Dados!S23:S32) -> 15802.24 | D4: =B4-C4 -> 6.6602409 | E4: =D4^2 -> 44.358809 | F4: ='Pesos Preditores (V)'!C4 -> 0.441 | G4: =E4*F4 -> 19.562235
A5: Trade (média 1981-1990) | B5: 56.777813 | C5: 56.939 | D5: =B5-C5 -> -0.16118742 | E5: =D5^2 -> 0.025981386 | F5: ='Pesos Preditores (V)'!C5 -> 0.134 | G5: =E5*F5 -> 0.0034815057
A6: Infrate (média 1981-1990) | B6: 2.5947991 | C6: 3.495 | D6: =B6-C6 -> -0.9002009 | E6: =D6^2 -> 0.81036167 | F6: ='Pesos Preditores (V)'!C6 -> 0.072 | G6: =E6*F6 -> 0.05834604
A7: Industry (média 1981-1990) | B7: 34.538488 | C7: 34.387 | D7: =B7-C7 -> 0.15148775 | E7: =D7^2 -> 0.022948539 | F7: ='Pesos Preditores (V)'!C7 -> 0.001 | G7: =E7*F7 -> 2.2948539e-05
A8: Schooling (média 1980,1985) | B8: 55.5 | C8: 55.18 | D8: =B8-C8 -> 0.32 | E8: =D8^2 -> 0.1024 | F8: ='Pesos Preditores (V)'!C8 -> 0.107 | G8: =E8*F8 -> 0.0109568
A9: Invest80 (1980) | B9: 27.017998 | C9: 27.034 | D9: =B9-C9 -> -0.016002258 | E9: =D9^2 -> 0.00025607227 | F9: ='Pesos Preditores (V)'!C9 -> 0.245 | G9: =E9*F9 -> 6.2737706e-05
G10: =SUM(G4:G9) -> 19.635105
